    r = adapter.send(request, **kwargs)
  File "C:\Eluminate\System\ImageScripter\lib\site-packages\requests\adapters.py", line 504, in send
    raise ConnectTimeout(e, request=request)
requests.exceptions.ConnectTimeout: HTTPConnectionPool(host='192.168.0.10', port=80): Max retries exceeded with url: /newlang1/login.html?uuid=%28ucc%3Bman%3A11nsbp%3Blan%3A0nsbp%3Bcon%3A0nsbp%3Bcom%3A0nsbp%3Balt%3AsCBv2grNiSzU4Or5mdaMmdaMmdaSn9AOnsbp%3Bname%3AEL-NVRnsbp%3B%29 (Caused by ConnectTimeoutError(<urllib3.connection.HTTPConnection object at 0x00000286C44BCD68>, 'Connection to 192.168.0.10 timed out. (connect timeout=1)'))

During handling of the above exception, another exception occurred:

Traceback (most recent call last):
  File "C:/Users/ken.shay/Desktop/WORKS.py", line 29, in <module>
    raise ValueError("Webui might be down")
ValueError: Webui might be down
