    Viewer.Start()
  File "C:\ImageScripter_3\lib\site-packages\elan\Custom_Applications.py", line 401, in Start
    ElanConnectPro.whitebox.WaitVanish()
  File "C:\ImageScripter_3\lib\site-packages\imagescripter\core\image.py", line 289, in WaitVanish
    result = self._application_object_._get_location_of_image_in_image(self._path_of_image_,self._application_object_._get_image_of_screen_(),threshold)
  File "C:\ImageScripter_3\lib\site-packages\imagescripter\core\device.py", line 95, in _get_location_of_image_in_image
    copyfile(target_img_path, file_name)
  File "C:\ImageScripter_3\lib\shutil.py", line 121, in copyfile
    with open(dst, 'wb') as fdst:
FileNotFoundError: [Errno 2] No such file or directory: 'C:\\Settings\\Comparison_Pictures\\1565641974.2606747.png'

During handling of the above exception, another exception occurred:

Traceback (most recent call last):
  File "C:\ImageScripter_3\\Lib\site-packages\imagescripter\core\imagescripter_script.py", line 317, in <module>
    script.run()
  File "C:\ImageScripter_3\\Lib\site-packages\imagescripter\core\imagescripter_script.py", line 246, in run
    self.get_and_enter_database_information_about_script()
  File "C:\ImageScripter_3\\Lib\site-packages\imagescripter\core\imagescripter_script.py", line 81, in get_and_enter_database_information_about_script
    Steps = self.get_script_text()
  File "C:\ImageScripter_3\\Lib\site-packages\imagescripter\core\imagescripter_script.py", line 53, in get_script_text
    with open(self.script_location,'r') as f:
FileNotFoundError: [Errno 2] No such file or directory: 'C:\\ImageScripter_2\\Lib\\site-packages\\elan\\Scripts\\Quick_Tests\\8_____Check_Network_Scanner___.py'
